<robot name="TPS_ROBOT">
    <link name="base_link">
    <inertial>
      <origin xyz="-0.00149408 -0.00013264 0.00946618" rpy="0 0 0" />
      <mass value="45" />
      <inertia ixx="0.52554437" iyy="2.11501347" izz="2.31892078" ixy="0.00435379" ixz="-0.0453884" iyz="-0.00042211"/>
    </inertial>
    <visual>
      <origin xyz="0 0 0" rpy="0 0 0" />
      <geometry>
        <mesh filename="file:///home/lizhen/works/code/OpenRobot/urdf_mjcf_autogenerator/robot_data/TPS/meshes/base_link.STL" scale="1 1 1"/>
      </geometry>
      <material name="">
        <color rgba="0.8 0.4 0 1" />
      </material>
    </visual>
    <collision>
      <origin xyz="0 0 0" rpy="0 0 0"/>
      <geometry>
        <mesh filename="file:///home/lizhen/works/code/OpenRobot/urdf_mjcf_autogenerator/robot_data/TPS/meshes/base_link.STL" scale="1 1 1"/>
      </geometry>
    </collision>
</link>

<link name="left_front_abad">
    <inertial>
      <origin xyz="0.0711798692039777 -0.00729665506584069 -0.00129271505229836" rpy="0 0 0" />
      <mass value="1.95556176300865" />
      <inertia ixx="0.00271333" iyy="0.00465758" izz="0.0043477" ixy="8.768e-05" ixz="-1.738e-05" iyz="-0.00013409"/>
    </inertial>
    <visual>
      <origin xyz="0 0 0" rpy="0 0 0" />
      <geometry>
        <mesh filename="file:///home/lizhen/works/code/OpenRobot/urdf_mjcf_autogenerator/robot_data/TPS/meshes/LF_HAA_link.STL" scale="1 1 1"/>
      </geometry>
      <material name="">
        <color rgba="1 0.4 0.4 1" />
      </material>
    </visual>
    <collision>
      <origin xyz="0 0 0" rpy="0 0 0"/>
      <geometry>
        <mesh filename="file:///home/lizhen/works/code/OpenRobot/urdf_mjcf_autogenerator/robot_data/TPS/meshes/LF_HAA_link.STL" scale="1 1 1"/>
      </geometry>
    </collision>
</link>

<joint name="idx01_left_front_abad" type="revolute">
    <origin xyz="0.315 0.0985 0" rpy="0 0 0" />
    <parent link="base_link" />
    <child link="left_front_abad" />
    <axis xyz="1 0 0" />
    <limit lower="-0.7854" upper="0.7854" effort="0" velocity="0" />
</joint>

<link name="left_front_hip">
    <inertial>
      <origin xyz="-0.00247582611684877 -0.0413093692230117 -0.0366450116801451" rpy="0 0 0" />
      <mass value="4.79806355897842" />
      <inertia ixx="0.04917354" iyy="0.04582942" izz="0.01398735" ixy="0.00049261" ixz="0.00214333" iyz="0.00669958"/>
    </inertial>
    <visual>
      <origin xyz="0 0 0" rpy="0 0 0" />
      <geometry>
        <mesh filename="file:///home/lizhen/works/code/OpenRobot/urdf_mjcf_autogenerator/robot_data/TPS/meshes/LF_HFE_link.STL" scale="1 1 1"/>
      </geometry>
      <material name="">
        <color rgba="1 1 0.4 1" />
      </material>
    </visual>
    <collision>
      <origin xyz="0 0 0" rpy="0 0 0"/>
      <geometry>
        <mesh filename="file:///home/lizhen/works/code/OpenRobot/urdf_mjcf_autogenerator/robot_data/TPS/meshes/LF_HFE_link.STL" scale="1 1 1"/>
      </geometry>
    </collision>
</link>

<joint name="idx02_left_front_hip" type="revolute">
    <origin xyz="0.078044 0.1527 -0.00057381" rpy="0 0 0" />
    <parent link="left_front_abad" />
    <child link="left_front_hip" />
    <axis xyz="0 1 0" />
    <limit lower="0.02967" upper="3.14" effort="0" velocity="0" />
</joint>

<link name="left_front_knee">
    <inertial>
      <origin xyz="0.01808524 0.00104266 -0.14475912" rpy="0 0 0" />
      <mass value="0.7" />
      <inertia ixx="0.0095021" iyy="0.00962198" izz="0.00027885" ixy="-3.3e-07" ixz="-0.00045839" iyz="-3.332e-05"/>
    </inertial>
    <visual>
      <origin xyz="0 0 0" rpy="0 0 0" />
      <geometry>
        <mesh filename="file:///home/lizhen/works/code/OpenRobot/urdf_mjcf_autogenerator/robot_data/TPS/meshes/LF_KFE_link.STL" scale="1 1 1"/>
      </geometry>
      <material name="">
        <color rgba="0.4 1 0.4 1" />
      </material>
    </visual>
    <collision>
      <origin xyz="0 0 0" rpy="0 0 0"/>
      <geometry>
        <mesh filename="file:///home/lizhen/works/code/OpenRobot/urdf_mjcf_autogenerator/robot_data/TPS/meshes/LF_KFE_link.STL" scale="1 1 1"/>
      </geometry>
    </collision>
</link>

<joint name="idx03_left_front_knee" type="revolute">
    <origin xyz="0 0 -0.30743" rpy="0 0 0" />
    <parent link="left_front_hip" />
    <child link="left_front_knee" />
    <axis xyz="0 1 0" />
    <limit lower="-2.742" upper="-1.137" effort="0" velocity="0" />
</joint>

<link name="left_front_foot">
    <inertial>
      <origin xyz="-0.00397021 2.712e-05 -0.00473186" rpy="0 0 0" />
      <mass value="0.05" />
      <inertia ixx="9.05e-05" iyy="0.0001052" izz="9.715e-05" ixy="3e-08" ixz="-1.868e-05" iyz="0"/>
    </inertial>
    <visual>
      <origin xyz="0 0 0" rpy="0 0 0" />
      <geometry>
        <mesh filename="file:///home/lizhen/works/code/OpenRobot/urdf_mjcf_autogenerator/robot_data/TPS/meshes/LF_FOOT_link.STL" scale="1 1 1"/>
      </geometry>
      <material name="">
        <color rgba="0 0.5 1 1" />
      </material>
    </visual>
    <collision>
      <origin xyz="0 0 0" rpy="0 0 0"/>
      <geometry>
        <mesh filename="file:///home/lizhen/works/code/OpenRobot/urdf_mjcf_autogenerator/robot_data/TPS/meshes/LF_FOOT_link.STL" scale="1 1 1"/>
      </geometry>
    </collision>
</link>

<joint name="idx04_left_front_foot" type="fixed">
    <origin xyz="-0.0019077 0.00099789 -0.31955" rpy="0 0 0" />
    <parent link="left_front_knee" />
    <child link="left_front_foot" />
    <axis xyz="0 1 0" />
    <limit lower="-2.742" upper="-1.137" effort="0" velocity="0" />
</joint>

<link name="left_rear_abad">
    <inertial>
      <origin xyz="-0.0711798692039777 -0.00729665506584069 -0.00129271505229836" rpy="0 0 0" />
      <mass value="1.95556176300865" />
      <inertia ixx="0.00271333" iyy="0.00465758" izz="0.0043477" ixy="8.768e-05" ixz="-1.738e-05" iyz="-0.00013409"/>
    </inertial>
    <visual>
      <origin xyz="0 0 0" rpy="0 0 0" />
      <geometry>
        <mesh filename="file:///home/lizhen/works/code/OpenRobot/urdf_mjcf_autogenerator/robot_data/TPS/meshes/LH_HAA_link.STL" scale="1 1 1"/>
      </geometry>
      <material name="">
        <color rgba="0.8 1.0 0.8 1" />
      </material>
    </visual>
    <collision>
      <origin xyz="0 0 0" rpy="0 0 0"/>
      <geometry>
        <mesh filename="file:///home/lizhen/works/code/OpenRobot/urdf_mjcf_autogenerator/robot_data/TPS/meshes/LH_HAA_link.STL" scale="1 1 1"/>
      </geometry>
    </collision>
</link>

<joint name="idx05_left_rear_abad" type="revolute">
    <origin xyz="-0.315 0.0985 0" rpy="0 0 0" />
    <parent link="base_link" />
    <child link="left_rear_abad" />
    <axis xyz="1 0 0" />
    <limit lower="-0.7854" upper="0.7854" effort="0" velocity="0" />
</joint>

<link name="left_rear_hip">
    <inertial>
      <origin xyz="-0.00247582611684877 -0.0413093692230117 -0.0366450116801451" rpy="0 0 0" />
      <mass value="4.79806355897842" />
      <inertia ixx="0.04917354" iyy="0.04582942" izz="0.01398735" ixy="0.00049261" ixz="0.00214333" iyz="0.00669958"/>
    </inertial>
    <visual>
      <origin xyz="0 0 0" rpy="0 0 0" />
      <geometry>
        <mesh filename="file:///home/lizhen/works/code/OpenRobot/urdf_mjcf_autogenerator/robot_data/TPS/meshes/LF_HFE_link.STL" scale="1 1 1"/>
      </geometry>
      <material name="">
        <color rgba="1 0.5 1 1" />
      </material>
    </visual>
    <collision>
      <origin xyz="0 0 0" rpy="0 0 0"/>
      <geometry>
        <mesh filename="file:///home/lizhen/works/code/OpenRobot/urdf_mjcf_autogenerator/robot_data/TPS/meshes/LF_HFE_link.STL" scale="1 1 1"/>
      </geometry>
    </collision>
</link>

<joint name="idx06_left_rear_hip" type="revolute">
    <origin xyz="-0.078044 0.1527 -0.00057381" rpy="0 0 0" />
    <parent link="left_rear_abad" />
    <child link="left_rear_hip" />
    <axis xyz="0 1 0" />
    <limit lower="0.02967" upper="3.14" effort="0" velocity="0" />
</joint>

<link name="left_rear_knee">
    <inertial>
      <origin xyz="0.01808524 0.00104266 -0.14475912" rpy="0 0 0" />
      <mass value="0.7" />
      <inertia ixx="0.0095021" iyy="0.00962198" izz="0.00027885" ixy="-3.3e-07" ixz="-0.00045839" iyz="-3.332e-05"/>
    </inertial>
    <visual>
      <origin xyz="0 0 0" rpy="0 0 0" />
      <geometry>
        <mesh filename="file:///home/lizhen/works/code/OpenRobot/urdf_mjcf_autogenerator/robot_data/TPS/meshes/LF_KFE_link.STL" scale="1 1 1"/>
      </geometry>
      <material name="">
        <color rgba="1 0.4 0.4 1" />
      </material>
    </visual>
    <collision>
      <origin xyz="0 0 0" rpy="0 0 0"/>
      <geometry>
        <mesh filename="file:///home/lizhen/works/code/OpenRobot/urdf_mjcf_autogenerator/robot_data/TPS/meshes/LF_KFE_link.STL" scale="1 1 1"/>
      </geometry>
    </collision>
</link>

<joint name="idx07_left_rear_knee" type="revolute">
    <origin xyz="0 0 -0.30743" rpy="0 0 0" />
    <parent link="left_rear_hip" />
    <child link="left_rear_knee" />
    <axis xyz="0 1 0" />
    <limit lower="-2.742" upper="-1.137" effort="0" velocity="0" />
</joint>

<link name="left_rear_foot">
    <inertial>
      <origin xyz="-0.00397021 2.712e-05 -0.00473186" rpy="0 0 0" />
      <mass value="0.05" />
      <inertia ixx="9.05e-05" iyy="0.0001052" izz="9.715e-05" ixy="3e-08" ixz="-1.868e-05" iyz="0"/>
    </inertial>
    <visual>
      <origin xyz="0 0 0" rpy="0 0 0" />
      <geometry>
        <mesh filename="file:///home/lizhen/works/code/OpenRobot/urdf_mjcf_autogenerator/robot_data/TPS/meshes/LF_FOOT_link.STL" scale="1 1 1"/>
      </geometry>
      <material name="">
        <color rgba="1 1 0.4 1" />
      </material>
    </visual>
    <collision>
      <origin xyz="0 0 0" rpy="0 0 0"/>
      <geometry>
        <mesh filename="file:///home/lizhen/works/code/OpenRobot/urdf_mjcf_autogenerator/robot_data/TPS/meshes/LF_FOOT_link.STL" scale="1 1 1"/>
      </geometry>
    </collision>
</link>

<joint name="idx08_left_rear_foot" type="fixed">
    <origin xyz="-0.0019077 0.00099789 -0.31955" rpy="0 0 0" />
    <parent link="left_rear_knee" />
    <child link="left_rear_foot" />
    <axis xyz="0 1 0" />
    <limit lower="-2.742" upper="-1.137" effort="0" velocity="0" />
</joint>

<link name="right_front_abad">
    <inertial>
      <origin xyz="0.0711798692039777 0.00729665506584069 -0.00129271505229836" rpy="0 0 0" />
      <mass value="1.95556176300865" />
      <inertia ixx="0.00271333" iyy="0.00465758" izz="0.0043477" ixy="-8.768e-05" ixz="-1.738e-05" iyz="0.00013409"/>
    </inertial>
    <visual>
      <origin xyz="0 0 0" rpy="0 0 0" />
      <geometry>
        <mesh filename="file:///home/lizhen/works/code/OpenRobot/urdf_mjcf_autogenerator/robot_data/TPS/meshes/LF_HAA_link.STL" scale="1.0 -1.0 1.0"/>
      </geometry>
      <material name="">
        <color rgba="1 0.4 0.4 1" />
      </material>
    </visual>
    <collision>
      <origin xyz="0 0 0" rpy="0 0 0"/>
      <geometry>
        <mesh filename="file:///home/lizhen/works/code/OpenRobot/urdf_mjcf_autogenerator/robot_data/TPS/meshes/LF_HAA_link.STL" scale="1.0 -1.0 1.0"/>
      </geometry>
    </collision>
</link>

<joint name="idx09_right_front_abad" type="revolute">
    <origin xyz="0.315 -0.0985 0.0" rpy="-0.0 0.0 -0.0" />
    <parent link="base_link" />
    <child link="right_front_abad" />
    <axis xyz="1 0 0" />
    <limit lower="-0.7854" upper="0.7854" effort="0" velocity="0" />
</joint>

<link name="right_front_hip">
    <inertial>
      <origin xyz="-0.00247582611684877 0.0413093692230117 -0.0366450116801451" rpy="0 0 0" />
      <mass value="4.79806355897842" />
      <inertia ixx="0.04917354" iyy="0.04582942" izz="0.01398735" ixy="-0.00049261" ixz="0.00214333" iyz="-0.00669958"/>
    </inertial>
    <visual>
      <origin xyz="0 0 0" rpy="0 0 0" />
      <geometry>
        <mesh filename="file:///home/lizhen/works/code/OpenRobot/urdf_mjcf_autogenerator/robot_data/TPS/meshes/LF_HFE_link.STL" scale="1.0 -1.0 1.0"/>
      </geometry>
      <material name="">
        <color rgba="1 1 0.4 1" />
      </material>
    </visual>
    <collision>
      <origin xyz="0 0 0" rpy="0 0 0"/>
      <geometry>
        <mesh filename="file:///home/lizhen/works/code/OpenRobot/urdf_mjcf_autogenerator/robot_data/TPS/meshes/LF_HFE_link.STL" scale="1.0 -1.0 1.0"/>
      </geometry>
    </collision>
</link>

<joint name="idx10_right_front_hip" type="revolute">
    <origin xyz="0.078044 -0.1527 -0.00057381" rpy="-0.0 0.0 -0.0" />
    <parent link="right_front_abad" />
    <child link="right_front_hip" />
    <axis xyz="0 1 0" />
    <limit lower="0.02967" upper="3.14" effort="0" velocity="0" />
</joint>

<link name="right_front_knee">
    <inertial>
      <origin xyz="0.01808524 -0.00104266 -0.14475912" rpy="0 0 0" />
      <mass value="0.7" />
      <inertia ixx="0.0095021" iyy="0.00962198" izz="0.00027885" ixy="3.3e-07" ixz="-0.00045839" iyz="3.332e-05"/>
    </inertial>
    <visual>
      <origin xyz="0 0 0" rpy="0 0 0" />
      <geometry>
        <mesh filename="file:///home/lizhen/works/code/OpenRobot/urdf_mjcf_autogenerator/robot_data/TPS/meshes/LF_KFE_link.STL" scale="1.0 -1.0 1.0"/>
      </geometry>
      <material name="">
        <color rgba="0.4 1 0.4 1" />
      </material>
    </visual>
    <collision>
      <origin xyz="0 0 0" rpy="0 0 0"/>
      <geometry>
        <mesh filename="file:///home/lizhen/works/code/OpenRobot/urdf_mjcf_autogenerator/robot_data/TPS/meshes/LF_KFE_link.STL" scale="1.0 -1.0 1.0"/>
      </geometry>
    </collision>
</link>

<joint name="idx11_right_front_knee" type="revolute">
    <origin xyz="0.0 -0.0 -0.30743" rpy="-0.0 0.0 -0.0" />
    <parent link="right_front_hip" />
    <child link="right_front_knee" />
    <axis xyz="0 1 0" />
    <limit lower="-2.742" upper="-1.137" effort="0" velocity="0" />
</joint>

<link name="right_front_foot">
    <inertial>
      <origin xyz="-0.00397021 -2.712e-05 -0.00473186" rpy="0 0 0" />
      <mass value="0.05" />
      <inertia ixx="9.05e-05" iyy="0.0001052" izz="9.715e-05" ixy="-3e-08" ixz="-1.868e-05" iyz="-0.0"/>
    </inertial>
    <visual>
      <origin xyz="0 0 0" rpy="0 0 0" />
      <geometry>
        <mesh filename="file:///home/lizhen/works/code/OpenRobot/urdf_mjcf_autogenerator/robot_data/TPS/meshes/LF_FOOT_link.STL" scale="1.0 -1.0 1.0"/>
      </geometry>
      <material name="">
        <color rgba="0 0.5 1 1" />
      </material>
    </visual>
    <collision>
      <origin xyz="0 0 0" rpy="0 0 0"/>
      <geometry>
        <mesh filename="file:///home/lizhen/works/code/OpenRobot/urdf_mjcf_autogenerator/robot_data/TPS/meshes/LF_FOOT_link.STL" scale="1.0 -1.0 1.0"/>
      </geometry>
    </collision>
</link>

<joint name="idx12_right_front_foot" type="fixed">
    <origin xyz="-0.0019077 -0.00099789 -0.31955" rpy="-0.0 0.0 -0.0" />
    <parent link="right_front_knee" />
    <child link="right_front_foot" />
    <axis xyz="0 1 0" />
    <limit lower="-2.742" upper="-1.137" effort="0" velocity="0" />
</joint>

<link name="right_rear_abad">
    <inertial>
      <origin xyz="-0.0711798692039777 0.00729665506584069 -0.00129271505229836" rpy="0 0 0" />
      <mass value="1.95556176300865" />
      <inertia ixx="0.00271333" iyy="0.00465758" izz="0.0043477" ixy="-8.768e-05" ixz="-1.738e-05" iyz="0.00013409"/>
    </inertial>
    <visual>
      <origin xyz="0 0 0" rpy="0 0 0" />
      <geometry>
        <mesh filename="file:///home/lizhen/works/code/OpenRobot/urdf_mjcf_autogenerator/robot_data/TPS/meshes/LH_HAA_link.STL" scale="1.0 -1.0 1.0"/>
      </geometry>
      <material name="">
        <color rgba="0.8 1.0 0.8 1" />
      </material>
    </visual>
    <collision>
      <origin xyz="0 0 0" rpy="0 0 0"/>
      <geometry>
        <mesh filename="file:///home/lizhen/works/code/OpenRobot/urdf_mjcf_autogenerator/robot_data/TPS/meshes/LH_HAA_link.STL" scale="1.0 -1.0 1.0"/>
      </geometry>
    </collision>
</link>

<joint name="idx13_right_rear_abad" type="revolute">
    <origin xyz="-0.315 -0.0985 0.0" rpy="-0.0 0.0 -0.0" />
    <parent link="base_link" />
    <child link="right_rear_abad" />
    <axis xyz="1 0 0" />
    <limit lower="-0.7854" upper="0.7854" effort="0" velocity="0" />
</joint>

<link name="right_rear_hip">
    <inertial>
      <origin xyz="-0.00247582611684877 0.0413093692230117 -0.0366450116801451" rpy="0 0 0" />
      <mass value="4.79806355897842" />
      <inertia ixx="0.04917354" iyy="0.04582942" izz="0.01398735" ixy="-0.00049261" ixz="0.00214333" iyz="-0.00669958"/>
    </inertial>
    <visual>
      <origin xyz="0 0 0" rpy="0 0 0" />
      <geometry>
        <mesh filename="file:///home/lizhen/works/code/OpenRobot/urdf_mjcf_autogenerator/robot_data/TPS/meshes/LF_HFE_link.STL" scale="1.0 -1.0 1.0"/>
      </geometry>
      <material name="">
        <color rgba="1 0.5 1 1" />
      </material>
    </visual>
    <collision>
      <origin xyz="0 0 0" rpy="0 0 0"/>
      <geometry>
        <mesh filename="file:///home/lizhen/works/code/OpenRobot/urdf_mjcf_autogenerator/robot_data/TPS/meshes/LF_HFE_link.STL" scale="1.0 -1.0 1.0"/>
      </geometry>
    </collision>
</link>

<joint name="idx14_right_rear_hip" type="revolute">
    <origin xyz="-0.078044 -0.1527 -0.00057381" rpy="-0.0 0.0 -0.0" />
    <parent link="right_rear_abad" />
    <child link="right_rear_hip" />
    <axis xyz="0 1 0" />
    <limit lower="0.02967" upper="3.14" effort="0" velocity="0" />
</joint>

<link name="right_rear_knee">
    <inertial>
      <origin xyz="0.01808524 -0.00104266 -0.14475912" rpy="0 0 0" />
      <mass value="0.7" />
      <inertia ixx="0.0095021" iyy="0.00962198" izz="0.00027885" ixy="3.3e-07" ixz="-0.00045839" iyz="3.332e-05"/>
    </inertial>
    <visual>
      <origin xyz="0 0 0" rpy="0 0 0" />
      <geometry>
        <mesh filename="file:///home/lizhen/works/code/OpenRobot/urdf_mjcf_autogenerator/robot_data/TPS/meshes/LF_KFE_link.STL" scale="1.0 -1.0 1.0"/>
      </geometry>
      <material name="">
        <color rgba="1 0.4 0.4 1" />
      </material>
    </visual>
    <collision>
      <origin xyz="0 0 0" rpy="0 0 0"/>
      <geometry>
        <mesh filename="file:///home/lizhen/works/code/OpenRobot/urdf_mjcf_autogenerator/robot_data/TPS/meshes/LF_KFE_link.STL" scale="1.0 -1.0 1.0"/>
      </geometry>
    </collision>
</link>

<joint name="idx15_right_rear_knee" type="revolute">
    <origin xyz="0.0 -0.0 -0.30743" rpy="-0.0 0.0 -0.0" />
    <parent link="right_rear_hip" />
    <child link="right_rear_knee" />
    <axis xyz="0 1 0" />
    <limit lower="-2.742" upper="-1.137" effort="0" velocity="0" />
</joint>

<link name="right_rear_foot">
    <inertial>
      <origin xyz="-0.00397021 -2.712e-05 -0.00473186" rpy="0 0 0" />
      <mass value="0.05" />
      <inertia ixx="9.05e-05" iyy="0.0001052" izz="9.715e-05" ixy="-3e-08" ixz="-1.868e-05" iyz="-0.0"/>
    </inertial>
    <visual>
      <origin xyz="0 0 0" rpy="0 0 0" />
      <geometry>
        <mesh filename="file:///home/lizhen/works/code/OpenRobot/urdf_mjcf_autogenerator/robot_data/TPS/meshes/LF_FOOT_link.STL" scale="1.0 -1.0 1.0"/>
      </geometry>
      <material name="">
        <color rgba="1 1 0.4 1" />
      </material>
    </visual>
    <collision>
      <origin xyz="0 0 0" rpy="0 0 0"/>
      <geometry>
        <mesh filename="file:///home/lizhen/works/code/OpenRobot/urdf_mjcf_autogenerator/robot_data/TPS/meshes/LF_FOOT_link.STL" scale="1.0 -1.0 1.0"/>
      </geometry>
    </collision>
</link>

<joint name="idx16_right_rear_foot" type="fixed">
    <origin xyz="-0.0019077 -0.00099789 -0.31955" rpy="-0.0 0.0 -0.0" />
    <parent link="right_rear_knee" />
    <child link="right_rear_foot" />
    <axis xyz="0 1 0" />
    <limit lower="-2.742" upper="-1.137" effort="0" velocity="0" />
</joint>

<!-- urdf auto generate tool -->
</robot>
