<mujoco model = "TPS_ROBOT">
    <compiler angle = 'radian' eulerseq = "XYZ" meshdir = "/home/lizhen/works/code/OpenRobot/urdf_mjcf_autogenerator/robot_data/TPS/meshes/" autolimits = "true" />

    <option timestep = "0.001" />

    <default>
        <geom contype = "0" conaffinity = "0" solref = "0.005 1" condim = "3" friction = "1 1" />
        <equality solref = "0.005 1" />
        <default class = "collision">
            <geom contype = "1" group = "3" type = "capsule" />
            <default class = "collision-left">
                <geom contype = "2" conaffinity = "4" />
            </default>
            <default class = "collision-right">
                <geom contype = "4" conaffinity = "2" />
            </default>
        </default>
    </default>

    <asset>
        <mesh name = "base_link_mesh_visual" file = "base_link.STL" scale = '1 1 1' />
        <mesh name = "base_link_mesh_collision" file = "base_link.STL" scale = '1 1 1' />
        <mesh name = "left_front_abad_mesh_visual" file = "LF_HAA_link.STL" scale = '1 1 1' />
        <mesh name = "left_front_abad_mesh_collision" file = "LF_HAA_link.STL" scale = '1 1 1' />
        <mesh name = "left_front_hip_mesh_visual" file = "LF_HFE_link.STL" scale = '1 1 1' />
        <mesh name = "left_front_hip_mesh_collision" file = "LF_HFE_link.STL" scale = '1 1 1' />
        <mesh name = "left_front_knee_mesh_visual" file = "LF_KFE_link.STL" scale = '1 1 1' />
        <mesh name = "left_front_knee_mesh_collision" file = "LF_KFE_link.STL" scale = '1 1 1' />
        <mesh name = "left_front_foot_mesh_visual" file = "LF_FOOT_link.STL" scale = '1 1 1' />
        <mesh name = "left_front_foot_mesh_collision" file = "LF_FOOT_link.STL" scale = '1 1 1' />
        <mesh name = "left_rear_abad_mesh_visual" file = "LH_HAA_link.STL" scale = '1 1 1' />
        <mesh name = "left_rear_abad_mesh_collision" file = "LH_HAA_link.STL" scale = '1 1 1' />
        <mesh name = "left_rear_hip_mesh_visual" file = "LF_HFE_link.STL" scale = '1 1 1' />
        <mesh name = "left_rear_hip_mesh_collision" file = "LF_HFE_link.STL" scale = '1 1 1' />
        <mesh name = "left_rear_knee_mesh_visual" file = "LF_KFE_link.STL" scale = '1 1 1' />
        <mesh name = "left_rear_knee_mesh_collision" file = "LF_KFE_link.STL" scale = '1 1 1' />
        <mesh name = "left_rear_foot_mesh_visual" file = "LF_FOOT_link.STL" scale = '1 1 1' />
        <mesh name = "left_rear_foot_mesh_collision" file = "LF_FOOT_link.STL" scale = '1 1 1' />
        <mesh name = "right_front_abad_mesh_visual" file = "LF_HAA_link.STL" scale = '1.0 -1.0 1.0' />
        <mesh name = "right_front_abad_mesh_collision" file = "LF_HAA_link.STL" scale = '1.0 -1.0 1.0' />
        <mesh name = "right_front_hip_mesh_visual" file = "LF_HFE_link.STL" scale = '1.0 -1.0 1.0' />
        <mesh name = "right_front_hip_mesh_collision" file = "LF_HFE_link.STL" scale = '1.0 -1.0 1.0' />
        <mesh name = "right_front_knee_mesh_visual" file = "LF_KFE_link.STL" scale = '1.0 -1.0 1.0' />
        <mesh name = "right_front_knee_mesh_collision" file = "LF_KFE_link.STL" scale = '1.0 -1.0 1.0' />
        <mesh name = "right_front_foot_mesh_visual" file = "LF_FOOT_link.STL" scale = '1.0 -1.0 1.0' />
        <mesh name = "right_front_foot_mesh_collision" file = "LF_FOOT_link.STL" scale = '1.0 -1.0 1.0' />
        <mesh name = "right_rear_abad_mesh_visual" file = "LH_HAA_link.STL" scale = '1.0 -1.0 1.0' />
        <mesh name = "right_rear_abad_mesh_collision" file = "LH_HAA_link.STL" scale = '1.0 -1.0 1.0' />
        <mesh name = "right_rear_hip_mesh_visual" file = "LF_HFE_link.STL" scale = '1.0 -1.0 1.0' />
        <mesh name = "right_rear_hip_mesh_collision" file = "LF_HFE_link.STL" scale = '1.0 -1.0 1.0' />
        <mesh name = "right_rear_knee_mesh_visual" file = "LF_KFE_link.STL" scale = '1.0 -1.0 1.0' />
        <mesh name = "right_rear_knee_mesh_collision" file = "LF_KFE_link.STL" scale = '1.0 -1.0 1.0' />
        <mesh name = "right_rear_foot_mesh_visual" file = "LF_FOOT_link.STL" scale = '1.0 -1.0 1.0' />
        <mesh name = "right_rear_foot_mesh_collision" file = "LF_FOOT_link.STL" scale = '1.0 -1.0 1.0' />
        <!-- asset auto generate -->
    </asset>

    <worldbody>
        <light name = "spotlight" mode = "targetbodycom" target = "base_link" pos = "0 -1 2" />
                
        <body name = 'base_link' pos = '0 0 0' euler = '0 0 0'>
            <inertial pos = "-0.00149408 -0.00013264 0.00946618" mass = "45" fullinertia = "0.52554437 2.11501347 2.31892078 0.00435379 -0.0453884 -0.00042211" />
            <freejoint />
            <site name = "imu" size = "0.01" pos = "0 0 0" />
            <geom type = 'mesh' mesh = 'base_link_mesh_visual' pos = '0 0 0' euler = '0 0 0' rgba = "0.8 0.4 0 1" />
            <geom type = 'mesh' mesh = 'base_link_mesh_collision' pos = '0 0 0' euler = '0 0 0' class = "collision" />
            <!-- base_link site geom -->
                        
            <body name = 'left_front_abad' pos = '0.315 0.0985 0' euler = '0 0 0'>
                <inertial pos = "0.0711798692039777 -0.00729665506584069 -0.00129271505229836" mass = "1.95556176300865" fullinertia = "0.00271333 0.00465758 0.0043477 8.768e-05 -1.738e-05 -0.00013409" />
                <joint name = 'idx01_left_front_abad' type = 'hinge' axis = '1 0 0' limited='true' range='-0.7854 0.7854' damping = '1' />
                <geom type = 'mesh' mesh = 'left_front_abad_mesh_visual' pos = '0 0 0' euler = '0 0 0' rgba = "1 0.4 0.4 1" />
                <geom type = 'mesh' mesh = 'left_front_abad_mesh_collision' pos = '0 0 0' euler = '0 0 0' class = "collision" />
                <!-- left_front_abad site geom -->
                                
                <body name = 'left_front_hip' pos = '0.078044 0.1527 -0.00057381' euler = '0 0 0'>
                    <inertial pos = "-0.00247582611684877 -0.0413093692230117 -0.0366450116801451" mass = "4.79806355897842" fullinertia = "0.04917354 0.04582942 0.01398735 0.00049261 0.00214333 0.00669958" />
                    <joint name = 'idx02_left_front_hip' type = 'hinge' axis = '0 1 0' limited='true' range='0.02967 3.14' damping = '1' />
                    <geom type = 'mesh' mesh = 'left_front_hip_mesh_visual' pos = '0 0 0' euler = '0 0 0' rgba = "1 1 0.4 1" />
                    <geom type = 'mesh' mesh = 'left_front_hip_mesh_collision' pos = '0 0 0' euler = '0 0 0' class = "collision" />
                    <!-- left_front_hip site geom -->
                                        
                    <body name = 'left_front_knee' pos = '0 0 -0.30743' euler = '0 0 0'>
                        <inertial pos = "0.01808524 0.00104266 -0.14475912" mass = "0.7" fullinertia = "0.0095021 0.00962198 0.00027885 -3.3e-07 -0.00045839 -3.332e-05" />
                        <joint name = 'idx03_left_front_knee' type = 'hinge' axis = '0 1 0' limited='true' range='-2.742 -1.137' damping = '1' />
                        <geom type = 'mesh' mesh = 'left_front_knee_mesh_visual' pos = '0 0 0' euler = '0 0 0' rgba = "0.4 1 0.4 1" />
                        <geom type = 'mesh' mesh = 'left_front_knee_mesh_collision' pos = '0 0 0' euler = '0 0 0' class = "collision" />
                        <!-- left_front_knee site geom -->
                                                
                        <body name = 'left_front_foot' pos = '-0.0019077 0.00099789 -0.31955' euler = '0 0 0'>
                            <inertial pos = "-0.00397021 2.712e-05 -0.00473186" mass = "0.05" fullinertia = "9.05e-05 0.0001052 9.715e-05 3e-08 -1.868e-05 0" />
                            <!-- left_front_foot joint -->
                            <geom type = 'mesh' mesh = 'left_front_foot_mesh_visual' pos = '0 0 0' euler = '0 0 0' rgba = "0 0.5 1 1" />
                            <geom type = 'mesh' mesh = 'left_front_foot_mesh_collision' pos = '0 0 0' euler = '0 0 0' class = "collision" />
                            <!-- left_front_foot site geom -->
                            <!-- left_front_foot child body -->
                        </body>
                        <!-- left_front_knee child body -->
                    </body>
                    <!-- left_front_hip child body -->
                </body>
                <!-- left_front_abad child body -->
            </body>
                        
            <body name = 'left_rear_abad' pos = '-0.315 0.0985 0' euler = '0 0 0'>
                <inertial pos = "-0.0711798692039777 -0.00729665506584069 -0.00129271505229836" mass = "1.95556176300865" fullinertia = "0.00271333 0.00465758 0.0043477 8.768e-05 -1.738e-05 -0.00013409" />
                <joint name = 'idx05_left_rear_abad' type = 'hinge' axis = '1 0 0' limited='true' range='-0.7854 0.7854' damping = '1' />
                <geom type = 'mesh' mesh = 'left_rear_abad_mesh_visual' pos = '0 0 0' euler = '0 0 0' rgba = "0.8 1.0 0.8 1" />
                <geom type = 'mesh' mesh = 'left_rear_abad_mesh_collision' pos = '0 0 0' euler = '0 0 0' class = "collision" />
                <!-- left_rear_abad site geom -->
                                
                <body name = 'left_rear_hip' pos = '-0.078044 0.1527 -0.00057381' euler = '0 0 0'>
                    <inertial pos = "-0.00247582611684877 -0.0413093692230117 -0.0366450116801451" mass = "4.79806355897842" fullinertia = "0.04917354 0.04582942 0.01398735 0.00049261 0.00214333 0.00669958" />
                    <joint name = 'idx06_left_rear_hip' type = 'hinge' axis = '0 1 0' limited='true' range='0.02967 3.14' damping = '1' />
                    <geom type = 'mesh' mesh = 'left_rear_hip_mesh_visual' pos = '0 0 0' euler = '0 0 0' rgba = "1 0.5 1 1" />
                    <geom type = 'mesh' mesh = 'left_rear_hip_mesh_collision' pos = '0 0 0' euler = '0 0 0' class = "collision" />
                    <!-- left_rear_hip site geom -->
                                        
                    <body name = 'left_rear_knee' pos = '0 0 -0.30743' euler = '0 0 0'>
                        <inertial pos = "0.01808524 0.00104266 -0.14475912" mass = "0.7" fullinertia = "0.0095021 0.00962198 0.00027885 -3.3e-07 -0.00045839 -3.332e-05" />
                        <joint name = 'idx07_left_rear_knee' type = 'hinge' axis = '0 1 0' limited='true' range='-2.742 -1.137' damping = '1' />
                        <geom type = 'mesh' mesh = 'left_rear_knee_mesh_visual' pos = '0 0 0' euler = '0 0 0' rgba = "1 0.4 0.4 1" />
                        <geom type = 'mesh' mesh = 'left_rear_knee_mesh_collision' pos = '0 0 0' euler = '0 0 0' class = "collision" />
                        <!-- left_rear_knee site geom -->
                                                
                        <body name = 'left_rear_foot' pos = '-0.0019077 0.00099789 -0.31955' euler = '0 0 0'>
                            <inertial pos = "-0.00397021 2.712e-05 -0.00473186" mass = "0.05" fullinertia = "9.05e-05 0.0001052 9.715e-05 3e-08 -1.868e-05 0" />
                            <!-- left_rear_foot joint -->
                            <geom type = 'mesh' mesh = 'left_rear_foot_mesh_visual' pos = '0 0 0' euler = '0 0 0' rgba = "1 1 0.4 1" />
                            <geom type = 'mesh' mesh = 'left_rear_foot_mesh_collision' pos = '0 0 0' euler = '0 0 0' class = "collision" />
                            <!-- left_rear_foot site geom -->
                            <!-- left_rear_foot child body -->
                        </body>
                        <!-- left_rear_knee child body -->
                    </body>
                    <!-- left_rear_hip child body -->
                </body>
                <!-- left_rear_abad child body -->
            </body>
                        
            <body name = 'right_front_abad' pos = '0.315 -0.0985 0.0' euler = '-0.0 0.0 -0.0'>
                <inertial pos = "0.0711798692039777 0.00729665506584069 -0.00129271505229836" mass = "1.95556176300865" fullinertia = "0.00271333 0.00465758 0.0043477 -8.768e-05 -1.738e-05 0.00013409" />
                <joint name = 'idx09_right_front_abad' type = 'hinge' axis = '1 0 0' limited='true' range='-0.7854 0.7854' damping = '1' />
                <geom type = 'mesh' mesh = 'right_front_abad_mesh_visual' pos = '0 0 0' euler = '0 0 0' rgba = "1 0.4 0.4 1" />
                <geom type = 'mesh' mesh = 'right_front_abad_mesh_collision' pos = '0 0 0' euler = '0 0 0' class = "collision" />
                <!-- right_front_abad site geom -->
                                
                <body name = 'right_front_hip' pos = '0.078044 -0.1527 -0.00057381' euler = '-0.0 0.0 -0.0'>
                    <inertial pos = "-0.00247582611684877 0.0413093692230117 -0.0366450116801451" mass = "4.79806355897842" fullinertia = "0.04917354 0.04582942 0.01398735 -0.00049261 0.00214333 -0.00669958" />
                    <joint name = 'idx10_right_front_hip' type = 'hinge' axis = '0 1 0' limited='true' range='0.02967 3.14' damping = '1' />
                    <geom type = 'mesh' mesh = 'right_front_hip_mesh_visual' pos = '0 0 0' euler = '0 0 0' rgba = "1 1 0.4 1" />
                    <geom type = 'mesh' mesh = 'right_front_hip_mesh_collision' pos = '0 0 0' euler = '0 0 0' class = "collision" />
                    <!-- right_front_hip site geom -->
                                        
                    <body name = 'right_front_knee' pos = '0.0 -0.0 -0.30743' euler = '-0.0 0.0 -0.0'>
                        <inertial pos = "0.01808524 -0.00104266 -0.14475912" mass = "0.7" fullinertia = "0.0095021 0.00962198 0.00027885 3.3e-07 -0.00045839 3.332e-05" />
                        <joint name = 'idx11_right_front_knee' type = 'hinge' axis = '0 1 0' limited='true' range='-2.742 -1.137' damping = '1' />
                        <geom type = 'mesh' mesh = 'right_front_knee_mesh_visual' pos = '0 0 0' euler = '0 0 0' rgba = "0.4 1 0.4 1" />
                        <geom type = 'mesh' mesh = 'right_front_knee_mesh_collision' pos = '0 0 0' euler = '0 0 0' class = "collision" />
                        <!-- right_front_knee site geom -->
                                                
                        <body name = 'right_front_foot' pos = '-0.0019077 -0.00099789 -0.31955' euler = '-0.0 0.0 -0.0'>
                            <inertial pos = "-0.00397021 -2.712e-05 -0.00473186" mass = "0.05" fullinertia = "9.05e-05 0.0001052 9.715e-05 -3e-08 -1.868e-05 -0.0" />
                            <!-- right_front_foot joint -->
                            <geom type = 'mesh' mesh = 'right_front_foot_mesh_visual' pos = '0 0 0' euler = '0 0 0' rgba = "0 0.5 1 1" />
                            <geom type = 'mesh' mesh = 'right_front_foot_mesh_collision' pos = '0 0 0' euler = '0 0 0' class = "collision" />
                            <!-- right_front_foot site geom -->
                            <!-- right_front_foot child body -->
                        </body>
                        <!-- right_front_knee child body -->
                    </body>
                    <!-- right_front_hip child body -->
                </body>
                <!-- right_front_abad child body -->
            </body>
                        
            <body name = 'right_rear_abad' pos = '-0.315 -0.0985 0.0' euler = '-0.0 0.0 -0.0'>
                <inertial pos = "-0.0711798692039777 0.00729665506584069 -0.00129271505229836" mass = "1.95556176300865" fullinertia = "0.00271333 0.00465758 0.0043477 -8.768e-05 -1.738e-05 0.00013409" />
                <joint name = 'idx13_right_rear_abad' type = 'hinge' axis = '1 0 0' limited='true' range='-0.7854 0.7854' damping = '1' />
                <geom type = 'mesh' mesh = 'right_rear_abad_mesh_visual' pos = '0 0 0' euler = '0 0 0' rgba = "0.8 1.0 0.8 1" />
                <geom type = 'mesh' mesh = 'right_rear_abad_mesh_collision' pos = '0 0 0' euler = '0 0 0' class = "collision" />
                <!-- right_rear_abad site geom -->
                                
                <body name = 'right_rear_hip' pos = '-0.078044 -0.1527 -0.00057381' euler = '-0.0 0.0 -0.0'>
                    <inertial pos = "-0.00247582611684877 0.0413093692230117 -0.0366450116801451" mass = "4.79806355897842" fullinertia = "0.04917354 0.04582942 0.01398735 -0.00049261 0.00214333 -0.00669958" />
                    <joint name = 'idx14_right_rear_hip' type = 'hinge' axis = '0 1 0' limited='true' range='0.02967 3.14' damping = '1' />
                    <geom type = 'mesh' mesh = 'right_rear_hip_mesh_visual' pos = '0 0 0' euler = '0 0 0' rgba = "1 0.5 1 1" />
                    <geom type = 'mesh' mesh = 'right_rear_hip_mesh_collision' pos = '0 0 0' euler = '0 0 0' class = "collision" />
                    <!-- right_rear_hip site geom -->
                                        
                    <body name = 'right_rear_knee' pos = '0.0 -0.0 -0.30743' euler = '-0.0 0.0 -0.0'>
                        <inertial pos = "0.01808524 -0.00104266 -0.14475912" mass = "0.7" fullinertia = "0.0095021 0.00962198 0.00027885 3.3e-07 -0.00045839 3.332e-05" />
                        <joint name = 'idx15_right_rear_knee' type = 'hinge' axis = '0 1 0' limited='true' range='-2.742 -1.137' damping = '1' />
                        <geom type = 'mesh' mesh = 'right_rear_knee_mesh_visual' pos = '0 0 0' euler = '0 0 0' rgba = "1 0.4 0.4 1" />
                        <geom type = 'mesh' mesh = 'right_rear_knee_mesh_collision' pos = '0 0 0' euler = '0 0 0' class = "collision" />
                        <!-- right_rear_knee site geom -->
                                                
                        <body name = 'right_rear_foot' pos = '-0.0019077 -0.00099789 -0.31955' euler = '-0.0 0.0 -0.0'>
                            <inertial pos = "-0.00397021 -2.712e-05 -0.00473186" mass = "0.05" fullinertia = "9.05e-05 0.0001052 9.715e-05 -3e-08 -1.868e-05 -0.0" />
                            <!-- right_rear_foot joint -->
                            <geom type = 'mesh' mesh = 'right_rear_foot_mesh_visual' pos = '0 0 0' euler = '0 0 0' rgba = "1 1 0.4 1" />
                            <geom type = 'mesh' mesh = 'right_rear_foot_mesh_collision' pos = '0 0 0' euler = '0 0 0' class = "collision" />
                            <!-- right_rear_foot site geom -->
                            <!-- right_rear_foot child body -->
                        </body>
                        <!-- right_rear_knee child body -->
                    </body>
                    <!-- right_rear_hip child body -->
                </body>
                <!-- right_rear_abad child body -->
            </body>
            <!-- base_link child body -->
        </body>
        <!-- world child body -->
    </worldbody>

    <actuator>
        <motor name = 'motor_idx01_left_front_abad' joint = 'idx01_left_front_abad' ctrlrange = '-0 0' />
        <motor name = 'motor_idx02_left_front_hip' joint = 'idx02_left_front_hip' ctrlrange = '-0 0' />
        <motor name = 'motor_idx03_left_front_knee' joint = 'idx03_left_front_knee' ctrlrange = '-0 0' />
        <motor name = 'motor_idx05_left_rear_abad' joint = 'idx05_left_rear_abad' ctrlrange = '-0 0' />
        <motor name = 'motor_idx06_left_rear_hip' joint = 'idx06_left_rear_hip' ctrlrange = '-0 0' />
        <motor name = 'motor_idx07_left_rear_knee' joint = 'idx07_left_rear_knee' ctrlrange = '-0 0' />
        <motor name = 'motor_idx09_right_front_abad' joint = 'idx09_right_front_abad' ctrlrange = '-0 0' />
        <motor name = 'motor_idx10_right_front_hip' joint = 'idx10_right_front_hip' ctrlrange = '-0 0' />
        <motor name = 'motor_idx11_right_front_knee' joint = 'idx11_right_front_knee' ctrlrange = '-0 0' />
        <motor name = 'motor_idx13_right_rear_abad' joint = 'idx13_right_rear_abad' ctrlrange = '-0 0' />
        <motor name = 'motor_idx14_right_rear_hip' joint = 'idx14_right_rear_hip' ctrlrange = '-0 0' />
        <motor name = 'motor_idx15_right_rear_knee' joint = 'idx15_right_rear_knee' ctrlrange = '-0 0' />
        <!-- actuator auto generate -->
    </actuator>

    <sensor>
        <jointpos name = 'jointpos_idx01_left_front_abad' joint = 'idx01_left_front_abad'/>
        <jointvel name = 'jointvel_idx01_left_front_abad' joint = 'idx01_left_front_abad'/>
        
        <jointpos name = 'jointpos_idx02_left_front_hip' joint = 'idx02_left_front_hip'/>
        <jointvel name = 'jointvel_idx02_left_front_hip' joint = 'idx02_left_front_hip'/>
        
        <jointpos name = 'jointpos_idx03_left_front_knee' joint = 'idx03_left_front_knee'/>
        <jointvel name = 'jointvel_idx03_left_front_knee' joint = 'idx03_left_front_knee'/>
        
        <jointpos name = 'jointpos_idx05_left_rear_abad' joint = 'idx05_left_rear_abad'/>
        <jointvel name = 'jointvel_idx05_left_rear_abad' joint = 'idx05_left_rear_abad'/>
        
        <jointpos name = 'jointpos_idx06_left_rear_hip' joint = 'idx06_left_rear_hip'/>
        <jointvel name = 'jointvel_idx06_left_rear_hip' joint = 'idx06_left_rear_hip'/>
        
        <jointpos name = 'jointpos_idx07_left_rear_knee' joint = 'idx07_left_rear_knee'/>
        <jointvel name = 'jointvel_idx07_left_rear_knee' joint = 'idx07_left_rear_knee'/>
        
        <jointpos name = 'jointpos_idx09_right_front_abad' joint = 'idx09_right_front_abad'/>
        <jointvel name = 'jointvel_idx09_right_front_abad' joint = 'idx09_right_front_abad'/>
        
        <jointpos name = 'jointpos_idx10_right_front_hip' joint = 'idx10_right_front_hip'/>
        <jointvel name = 'jointvel_idx10_right_front_hip' joint = 'idx10_right_front_hip'/>
        
        <jointpos name = 'jointpos_idx11_right_front_knee' joint = 'idx11_right_front_knee'/>
        <jointvel name = 'jointvel_idx11_right_front_knee' joint = 'idx11_right_front_knee'/>
        
        <jointpos name = 'jointpos_idx13_right_rear_abad' joint = 'idx13_right_rear_abad'/>
        <jointvel name = 'jointvel_idx13_right_rear_abad' joint = 'idx13_right_rear_abad'/>
        
        <jointpos name = 'jointpos_idx14_right_rear_hip' joint = 'idx14_right_rear_hip'/>
        <jointvel name = 'jointvel_idx14_right_rear_hip' joint = 'idx14_right_rear_hip'/>
        
        <jointpos name = 'jointpos_idx15_right_rear_knee' joint = 'idx15_right_rear_knee'/>
        <jointvel name = 'jointvel_idx15_right_rear_knee' joint = 'idx15_right_rear_knee'/>
        
        <!-- sensor auto generate -->
    </sensor>
    <!--
    <equality>
        <connect name = '' body1 = '' body2 = '' solimp = '0.9999 0.9999 0.001 0.5 2' anchor = '0 0 0' />
    </equality>
    -->
    <sensor>
        <framequat name="body-orientation" objtype="site" objname="imu"/>
        <gyro name="body-angular-velocity" site="imu"/>
        <framepos name="body-linear-pos" objtype="site" objname="imu"/>
        <velocimeter name="body-linear-vel" site="imu"/>
        <accelerometer name="body-linear-acceleration" site="imu"/>
    </sensor>

    <!--
    <keyframe>
        <key name = "default" qpos = "" />
    </keyframe>
    -->
</mujoco>